Workbook

Sheet Sheet1
A2: SEBELAS MARET UNIVERSITY
B4: Faculty | C4: TEKNIK
B5: Study program | C5: Industri
B6: Academic year | C6: 2022 - Ganjil
B7: Course Code | C7: TI191107
B8: Course Name | C8: Menggambar Teknik
B9: Class | C9: A
B10: Lecturer | C10: YUSUF PRIYANDARI
B11: X/lPZv53FpITM7HKFHEpoOUbJenWYS3iLpupsxxW2Jg=
A12: No | B12: Nim | C12: Mahasiswa | D12: Nilai
D13: UK3 | E13: UK4 | F13: UK1 (UTS) | G13: UK2 (UAS) | H13: UK5
D14: 1 | E14: 1 | F14: 3 | G14: 3 | H14: 2
A15: 1 | B15: I0322001 | C15: ACHMAD SIDIQ HERMAN | D15: ='CP1.26'!L15 -> 90 | E15: ='CP1.27'!M15 -> 87.5 | F15: ='CP1.28'!J15 -> 86 | G15: ='CP1.29'!L15 -> 91 | H15: ='CP1.30'!L15 -> 87.75 | L15: =(D15+E15+3*F15+3*G15+2*H15)/10 -> 88.4
A16: 2 | B16: I0322002 | C16: ADITYA AGUNG NUGROHO | D16: ='CP1.26'!L16 -> 90 | E16: ='CP1.27'!M16 -> 62.5 | F16: ='CP1.28'!J16 -> 85.333333 | G16: ='CP1.29'!L16 -> 91 | H16: ='CP1.30'!L16 -> 84 | L16: =(D16+E16+3*F16+3*G16+2*H16)/10 -> 84.95
A17: 3 | B17: I0322003 | C17: ADITYA SYAHRIAL VALENTIO | D17: ='CP1.26'!L17 -> - | L17: =(D17+E17+3*F17+3*G17+2*H17)/10 -> #VALUE!
A18: 4 | B18: I0322004 | C18: ADRIANI HASNA KHALISHA | D18: ='CP1.26'!L18 -> 83 | E18: ='CP1.27'!M18 -> 68.75 | F18: ='CP1.28'!J18 -> 85.333333 | G18: ='CP1.29'!L18 -> 82 | H18: ='CP1.30'!L18 -> 83 | L18: =(D18+E18+3*F18+3*G18+2*H18)/10 -> 81.975
A19: 5 | B19: I0322005 | C19: ADZ-DZIKRA QUROTA A'YUN | D19: ='CP1.26'!L19 -> 83 | E19: ='CP1.27'!M19 -> 0 | F19: ='CP1.28'!J19 -> 87 | G19: ='CP1.29'!L19 -> 85 | H19: ='CP1.30'!L19 -> 79.75 | L19: =(D19+E19+3*F19+3*G19+2*H19)/10 -> 75.85
A20: 6 | B20: I0322006 | C20: AHMAD JANGKUNG ISLAMUDIN | D20: ='CP1.26'!L20 -> 90 | E20: ='CP1.27'!M20 -> 56.25 | F20: ='CP1.28'!J20 -> 84.333333 | G20: ='CP1.29'!L20 -> 82 | H20: ='CP1.30'!L20 -> 83 | L20: =(D20+E20+3*F20+3*G20+2*H20)/10 -> 81.125
A21: 7 | B21: I0322007 | C21: AKBAR SATYA PAMBUDI | D21: ='CP1.26'!L21 -> - | L21: =(D21+E21+3*F21+3*G21+2*H21)/10 -> #VALUE!
A22: 8 | B22: I0322008 | C22: AKEYSHA BELVA DEVARA | D22: ='CP1.26'!L22 -> 83 | E22: ='CP1.27'!M22 -> 0 | F22: ='CP1.28'!J22 -> 84.666667 | G22: ='CP1.29'!L22 -> 89 | H22: ='CP1.30'!L22 -> 86.5 | L22: =(D22+E22+3*F22+3*G22+2*H22)/10 -> 77.7
A23: 9 | B23: I0322009 | C23: AKILA SYAHRA MAHARANI | D23: ='CP1.26'!L23 -> 83 | E23: ='CP1.27'!M23 -> 0 | F23: ='CP1.28'!J23 -> 79.666667 | G23: ='CP1.29'!L23 -> 92 | H23: ='CP1.30'!L23 -> 85.75 | L23: =(D23+E23+3*F23+3*G23+2*H23)/10 -> 76.95
A24: 10 | B24: I0322010 | C24: ALAMSYAH RIYO SAPUTRA | D24: ='CP1.26'!L24 -> 90 | E24: ='CP1.27'!M24 -> 0 | F24: ='CP1.28'!J24 -> 80.666667 | G24: ='CP1.29'!L24 -> 89 | H24: ='CP1.30'!L24 -> 86.5 | L24: =(D24+E24+3*F24+3*G24+2*H24)/10 -> 77.2
A25: 11 | B25: I0322011 | C25: ALIF KUS SETYANTO | D25: ='CP1.26'!L25 -> 90 | E25: ='CP1.27'!M25 -> 81.25 | F25: ='CP1.28'!J25 -> 83 | G25: ='CP1.29'!L25 -> 89 | H25: ='CP1.30'!L25 -> 86.5 | L25: =(D25+E25+3*F25+3*G25+2*H25)/10 -> 86.025
A26: 12 | B26: I0322012 | C26: ALRANTISA AMIENA RAISA | D26: ='CP1.26'!L26 -> 75 | E26: ='CP1.27'!M26 -> 50 | F26: ='CP1.28'!J26 -> 78.333333 | G26: ='CP1.29'!L26 -> 85 | H26: ='CP1.30'!L26 -> 79.75 | L26: =(D26+E26+3*F26+3*G26+2*H26)/10 -> 77.45
A27: 13 | B27: I0322013 | C27: ANCELIN ALOYSIA PRASETYO | D27: ='CP1.26'!L27 -> 90 | E27: ='CP1.27'!M27 -> 75 | F27: ='CP1.28'!J27 -> 84 | G27: ='CP1.29'!L27 -> 91 | H27: ='CP1.30'!L27 -> 84 | L27: =(D27+E27+3*F27+3*G27+2*H27)/10 -> 85.8
A28: 14 | B28: I0322014 | C28: ANGELIQUE YOANITA | D28: ='CP1.26'!L28 -> 90 | E28: ='CP1.27'!M28 -> 56.25 | F28: ='CP1.28'!J28 -> 80 | G28: ='CP1.29'!L28 -> 82 | H28: ='CP1.30'!L28 -> 83 | L28: =(D28+E28+3*F28+3*G28+2*H28)/10 -> 79.825
A29: 15 | B29: I0322015 | C29: ANGGITO DWI PRIHANTORO | D29: ='CP1.26'!L29 -> 90 | E29: ='CP1.27'!M29 -> 75 | F29: ='CP1.28'!J29 -> 85.333333 | G29: ='CP1.29'!L29 -> 92 | H29: ='CP1.30'!L29 -> 85.75 | L29: =(D29+E29+3*F29+3*G29+2*H29)/10 -> 86.85
A30: 16 | B30: I0322016 | C30: ANTONIUS INDRA WICAKSONO | D30: ='CP1.26'!L30 -> 83 | E30: ='CP1.27'!M30 -> 56.25 | F30: ='CP1.28'!J30 -> 82.333333 | G30: ='CP1.29'!L30 -> 89 | H30: ='CP1.30'!L30 -> 86.5 | L30: =(D30+E30+3*F30+3*G30+2*H30)/10 -> 82.625
A31: 17 | B31: I0322017 | C31: ARIIQ RAKHMAN SETIANA | D31: ='CP1.26'!L31 -> 90 | E31: ='CP1.27'!M31 -> 68.75 | F31: ='CP1.28'!J31 -> 63.666667 | G31: ='CP1.29'!L31 -> 91 | H31: ='CP1.30'!L31 -> 87.75 | L31: =(D31+E31+3*F31+3*G31+2*H31)/10 -> 79.825
A32: 18 | B32: I0322018 | C32: AUDRY ANGELINA LUBIS | D32: ='CP1.26'!L32 -> 83 | E32: ='CP1.27'!M32 -> 56.25 | F32: ='CP1.28'!J32 -> 77.333333 | G32: ='CP1.29'!L32 -> 91 | H32: ='CP1.30'!L32 -> 87.75 | L32: =(D32+E32+3*F32+3*G32+2*H32)/10 -> 81.975
A33: 19 | B33: I0322019 | C33: AURELIA NADIRA ROSEKANIA DARMAWAN | D33: ='CP1.26'!L33 -> 78 | E33: ='CP1.27'!M33 -> 56.25 | F33: ='CP1.28'!J33 -> 71 | G33: ='CP1.29'!L33 -> 91 | H33: ='CP1.30'!L33 -> 84 | L33: =(D33+E33+3*F33+3*G33+2*H33)/10 -> 78.825
... A43: 29 | B43: I0322029 | C43: CHILYA ULIL FITRIA | D43: ='CP1.26'!L43 -> 75 | E43: ='CP1.27'!M43 -> 62.5 | F43: ='CP1.28'!J43 -> 82.333333 | G43: ='CP1.29'!L43 -> 91 | H43: ='CP1.30'!L43 -> 87.75 | L43: =(D43+E43+3*F43+3*G43+2*H43)/10 -> 83.3
A44: 30 | B44: I0322030 | C44: DAFFA RASYAD WIRA NUGROHO | D44: ='CP1.26'!L44 -> - | L44: =(D44+E44+3*F44+3*G44+2*H44)/10 -> #VALUE!
A45: 31 | B45: I0322031 | C45: DANIALIN SISWO HANDOYO | D45: ='CP1.26'!L45 -> 90 | E45: ='CP1.27'!M45 -> 25 | F45: ='CP1.28'!J45 -> 82.333333 | G45: ='CP1.29'!L45 -> 92 | H45: ='CP1.30'!L45 -> 85.75 | L45: =(D45+E45+3*F45+3*G45+2*H45)/10 -> 80.95
A46: 32 | B46: I0322032 | C46: DANIEL MULASATRIA DAMANIK | D46: ='CP1.26'!L46 -> 75 | E46: ='CP1.27'!M46 -> 68.75 | F46: ='CP1.28'!J46 -> 84 | G46: ='CP1.29'!L46 -> 82 | H46: ='CP1.30'!L46 -> 83 | L46: =(D46+E46+3*F46+3*G46+2*H46)/10 -> 80.775
A47: 33 | B47: I0322033 | C47: DANU ILMAM AHARY | D47: ='CP1.26'!L47 -> - | L47: =(D47+E47+3*F47+3*G47+2*H47)/10 -> #VALUE!
A48: 34 | B48: I0322034 | C48: DEANIETA ADILEST | D48: ='CP1.26'!L48 -> 75 | E48: ='CP1.27'!M48 -> 56.25 | F48: ='CP1.28'!J48 -> 83.333333 | G48: ='CP1.29'!L48 -> 91 | H48: ='CP1.30'!L48 -> 84 | L48: =(D48+E48+3*F48+3*G48+2*H48)/10 -> 82.225
A49: 35 | B49: I0322035 | C49: DENNISA LATHIFA HARDIANI | D49: ='CP1.26'!L49 -> 75 | E49: ='CP1.27'!M49 -> 62.5 | F49: ='CP1.28'!J49 -> 82.333333 | G49: ='CP1.29'!L49 -> 91 | H49: ='CP1.30'!L49 -> 84 | L49: =(D49+E49+3*F49+3*G49+2*H49)/10 -> 82.55

Sheet CP1.26
A2: SEBELAS MARET UNIVERSITY
B4: Faculty | C4: TEKNIK | L4: Tolong inputkan nilai Aktivitas Mandiri
B5: Study program | C5: Industri | L5: Grup | M5: Nilai
B6: Academic year | C6: 2022 - Ganjil | L6: I | M6: 90
B7: Course Code | C7: TI191107 | L7: II | M7: 83
B8: Course Name | C8: Menggambar Teknik | L8: III | M8: 78
B9: Class | C9: A | L9: IV | M9: 75
B10: Lecturer | C10: YUSUF PRIYANDARI
B11: X/lPZv53FpITM7HKFHEpoOUbJenWYS3iLpupsxxW2Jg=
A12: No | B12: Nim | C12: Mahasiswa | D12: Nilai | L12: NILAI
D13: UK3 | E13: UK4 | F13: UK1 (UTS) | G13: UK2 (UAS) | H13: UK5 | L13: GeCOns2D
D14: 0 | E14: 0 | F14: 1 | G14: 1 | H14: 0
A15: 1 | B15: I0322001 | C15: ACHMAD SIDIQ HERMAN | L15: 90
A16: 2 | B16: I0322002 | C16: ADITYA AGUNG NUGROHO | L16: 90
A17: 3 | B17: I0322003 | C17: ADITYA SYAHRIAL VALENTIO | L17: -
A18: 4 | B18: I0322004 | C18: ADRIANI HASNA KHALISHA | L18: 83
A19: 5 | B19: I0322005 | C19: ADZ-DZIKRA QUROTA A'YUN | L19: 83
A20: 6 | B20: I0322006 | C20: AHMAD JANGKUNG ISLAMUDIN | L20: 90
A21: 7 | B21: I0322007 | C21: AKBAR SATYA PAMBUDI | L21: -
A22: 8 | B22: I0322008 | C22: AKEYSHA BELVA DEVARA | L22: 83
A23: 9 | B23: I0322009 | C23: AKILA SYAHRA MAHARANI | L23: 83
A24: 10 | B24: I0322010 | C24: ALAMSYAH RIYO SAPUTRA | L24: 90
A25: 11 | B25: I0322011 | C25: ALIF KUS SETYANTO | L25: 90
A26: 12 | B26: I0322012 | C26: ALRANTISA AMIENA RAISA | L26: 75
A27: 13 | B27: I0322013 | C27: ANCELIN ALOYSIA PRASETYO | L27: 90
A28: 14 | B28: I0322014 | C28: ANGELIQUE YOANITA | L28: 90
A29: 15 | B29: I0322015 | C29: ANGGITO DWI PRIHANTORO | L29: 90
A30: 16 | B30: I0322016 | C30: ANTONIUS INDRA WICAKSONO | L30: 83
A31: 17 | B31: I0322017 | C31: ARIIQ RAKHMAN SETIANA | L31: 90
A32: 18 | B32: I0322018 | C32: AUDRY ANGELINA LUBIS | L32: 83
A33: 19 | B33: I0322019 | C33: AURELIA NADIRA ROSEKANIA DARMAWAN | L33: 78
... A43: 29 | B43: I0322029 | C43: CHILYA ULIL FITRIA | L43: 75
A44: 30 | B44: I0322030 | C44: DAFFA RASYAD WIRA NUGROHO | L44: -
A45: 31 | B45: I0322031 | C45: DANIALIN SISWO HANDOYO | L45: 90
A46: 32 | B46: I0322032 | C46: DANIEL MULASATRIA DAMANIK | L46: 75
A47: 33 | B47: I0322033 | C47: DANU ILMAM AHARY | L47: -
A48: 34 | B48: I0322034 | C48: DEANIETA ADILEST | L48: 75
A49: 35 | B49: I0322035 | C49: DENNISA LATHIFA HARDIANI | L49: 75

Sheet CP1.27
A2: SEBELAS MARET UNIVERSITY
B4: Faculty | C4: TEKNIK
B5: Study program | C5: Industri
B6: Academic year | C6: 2022 - Ganjil
B7: Course Code | C7: TI191107
B8: Course Name | C8: Menggambar Teknik
B9: Class | C9: A
B10: Lecturer | C10: YUSUF PRIYANDARI
B11: X/lPZv53FpITM7HKFHEpoOUbJenWYS3iLpupsxxW2Jg=
A12: No | B12: Nim | C12: Mahasiswa | D12: Nilai
D13: UK3 | E13: UK4 | F13: UK1 (UTS) | G13: UK2 (UAS) | H13: UK5 | L13: Skor | M13: NIlai
D14: 0 | E14: 0 | F14: 1 | G14: 1 | H14: 0
A15: 1 | B15: I0322001 | C15: ACHMAD SIDIQ HERMAN | L15: 14 | M15: =(L15/16)*100 -> 87.5
A16: 1 | B16: I0322002 | C16: ADITYA AGUNG NUGROHO | L16: 10 | M16: =(L16/16)*100 -> 62.5
A17: 1 | B17: I0322003 | C17: ADITYA SYAHRIAL VALENTIO | M17: =(L17/16)*100 -> 0
A18: 1 | B18: I0322004 | C18: ADRIANI HASNA KHALISHA | L18: 11 | M18: =(L18/16)*100 -> 68.75
A19: 5 | B19: I0322005 | C19: ADZ-DZIKRA QUROTA A'YUN | M19: =(L19/16)*100 -> 0
A20: 6 | B20: I0322006 | C20: AHMAD JANGKUNG ISLAMUDIN | L20: 9 | M20: =(L20/16)*100 -> 56.25
A21: 7 | B21: I0322007 | C21: AKBAR SATYA PAMBUDI | M21: =(L21/16)*100 -> 0
A22: 8 | B22: I0322008 | C22: AKEYSHA BELVA DEVARA | M22: =(L22/16)*100 -> 0
A23: 9 | B23: I0322009 | C23: AKILA SYAHRA MAHARANI | M23: =(L23/16)*100 -> 0
A24: 10 | B24: I0322010 | C24: ALAMSYAH RIYO SAPUTRA | M24: =(L24/16)*100 -> 0
A25: 11 | B25: I0322011 | C25: ALIF KUS SETYANTO | L25: 13 | M25: =(L25/16)*100 -> 81.25
A26: 12 | B26: I0322012 | C26: ALRANTISA AMIENA RAISA | L26: 8 | M26: =(L26/16)*100 -> 50
A27: 13 | B27: I0322013 | C27: ANCELIN ALOYSIA PRASETYO | L27: 12 | M27: =(L27/16)*100 -> 75
A28: 14 | B28: I0322014 | C28: ANGELIQUE YOANITA | L28: 9 | M28: =(L28/16)*100 -> 56.25
A29: 15 | B29: I0322015 | C29: ANGGITO DWI PRIHANTORO | L29: 12 | M29: =(L29/16)*100 -> 75
A30: 16 | B30: I0322016 | C30: ANTONIUS INDRA WICAKSONO | L30: 9 | M30: =(L30/16)*100 -> 56.25
A31: 17 | B31: I0322017 | C31: ARIIQ RAKHMAN SETIANA | L31: 11 | M31: =(L31/16)*100 -> 68.75
A32: 18 | B32: I0322018 | C32: AUDRY ANGELINA LUBIS | L32: 9 | M32: =(L32/16)*100 -> 56.25
A33: 19 | B33: I0322019 | C33: AURELIA NADIRA ROSEKANIA DARMAWAN | L33: 9 | M33: =(L33/16)*100 -> 56.25
A34: 20 | B34: I0322020 | C34: AYUSIKA YUMNA AGIL NABILLAH | L34: 11 | M34: =(L34/16)*100 -> 68.75
A35: 21 | B35: I0322021 | C35: AZIS HENDRAWAN | M35: =(L35/16)*100 -> 0
A36: 22 | B36: I0322022 | C36: BAGUS PRADITA | L36: 10 | M36: =(L36/16)*100 -> 62.5
A37: 23 | B37: I0322023 | C37: BAGUS RAKHA PRAMUDITYA | L37: 11 | M37: =(L37/16)*100 -> 68.75
A38: 24 | B38: I0322024 | C38: BERLIANA NURUL AZZAHRA | L38: 10 | M38: =(L38/16)*100 -> 62.5
A39: 25 | B39: I0322025 | C39: BRIAN WINSON JO | L39: 13 | M39: =(L39/16)*100 -> 81.25
A40: 26 | B40: I0322026 | C40: CHANISA ULKARIMAH | M40: =(L40/16)*100 -> 0
A41: 27 | B41: I0322027 | C41: CHARISMA CINTANI ADHI SURYA | M41: =(L41/16)*100 -> 0
A42: 28 | B42: I0322028 | C42: CHEZAVA DEANANTA | L42: 7 | M42: =(L42/16)*100 -> 43.75
...

Sheet CP1.28
A2: SEBELAS MARET UNIVERSITY
B4: Faculty | C4: TEKNIK
B5: Study program | C5: Industri
B6: Academic year | C6: 2022 - Ganjil
B7: Course Code | C7: TI191107
B8: Course Name | C8: Menggambar Teknik
B9: Class | C9: A
B10: Lecturer | C10: YUSUF PRIYANDARI
B11: X/lPZv53FpITM7HKFHEpoOUbJenWYS3iLpupsxxW2Jg=
A12: No | B12: Nim | C12: Mahasiswa | D12: Nilai
D13: UK3 | E13: UK4 | F13: UK1 (UTS) | G13: UK2 (UAS) | H13: UK5 | L13: NIlai
D14: 0 | E14: 0 | F14: 1 | G14: 1 | H14: 0
A15: 1 | B15: I0322001 | C15: ACHMAD SIDIQ HERMAN | I15: I0322001 | J15: 86
A16: 2 | B16: I0322002 | C16: ADITYA AGUNG NUGROHO | I16: I0322002 | J16: 85.333333
A17: 3 | B17: I0322003 | C17: ADITYA SYAHRIAL VALENTIO
A18: 4 | B18: I0322004 | C18: ADRIANI HASNA KHALISHA | I18: I0322004 | J18: 85.333333
A19: 5 | B19: I0322005 | C19: ADZ-DZIKRA QUROTA A'YUN | I19: I0322005 | J19: 87
A20: 6 | B20: I0322006 | C20: AHMAD JANGKUNG ISLAMUDIN | I20: I0322006 | J20: 84.333333
A21: 7 | B21: I0322007 | C21: AKBAR SATYA PAMBUDI
A22: 8 | B22: I0322008 | C22: AKEYSHA BELVA DEVARA | I22: I0322008 | J22: 84.666667
A23: 9 | B23: I0322009 | C23: AKILA SYAHRA MAHARANI | I23: I0322009 | J23: 79.666667
A24: 10 | B24: I0322010 | C24: ALAMSYAH RIYO SAPUTRA | I24: I0322010 | J24: 80.666667
A25: 11 | B25: I0322011 | C25: ALIF KUS SETYANTO | I25: I0322011 | J25: 83
A26: 12 | B26: I0322012 | C26: ALRANTISA AMIENA RAISA | I26: I0322012 | J26: 78.333333
A27: 13 | B27: I0322013 | C27: ANCELIN ALOYSIA PRASETYO | I27: I0322013 | J27: 84
A28: 14 | B28: I0322014 | C28: ANGELIQUE YOANITA | I28: I0322014 | J28: 80
A29: 15 | B29: I0322015 | C29: ANGGITO DWI PRIHANTORO | I29: I0322015 | J29: 85.333333
A30: 16 | B30: I0322016 | C30: ANTONIUS INDRA WICAKSONO | I30: I0322016 | J30: 82.333333
A31: 17 | B31: I0322017 | C31: ARIIQ RAKHMAN SETIANA | I31: I0322017 | J31: 63.666667
A32: 18 | B32: I0322018 | C32: AUDRY ANGELINA LUBIS | I32: I0322018 | J32: 77.333333
A33: 19 | B33: I0322019 | C33: AURELIA NADIRA ROSEKANIA DARMAWAN | I33: I0322019 | J33: 71
... A43: 29 | B43: I0322029 | C43: CHILYA ULIL FITRIA | I43: I0322029 | J43: 82.333333
A44: 30 | B44: I0322030 | C44: DAFFA RASYAD WIRA NUGROHO
A45: 31 | B45: I0322031 | C45: DANIALIN SISWO HANDOYO | I45: I0322031 | J45: 82.333333
A46: 32 | B46: I0322032 | C46: DANIEL MULASATRIA DAMANIK | I46: I0322032 | J46: 84
A47: 33 | B47: I0322033 | C47: DANU ILMAM AHARY
A48: 34 | B48: I0322034 | C48: DEANIETA ADILEST | I48: I0322034 | J48: 83.333333
A49: 35 | B49: I0322035 | C49: DENNISA LATHIFA HARDIANI | I49: I0322035 | J49: 82.333333

Sheet CP1.29
A2: SEBELAS MARET UNIVERSITY
B4: Faculty | C4: TEKNIK
B5: Study program | C5: Industri
B6: Academic year | C6: 2022 - Ganjil
B7: Course Code | C7: TI191107
B8: Course Name | C8: Menggambar Teknik
B9: Class | C9: A
B10: Lecturer | C10: YUSUF PRIYANDARI
B11: X/lPZv53FpITM7HKFHEpoOUbJenWYS3iLpupsxxW2Jg=
A12: No | B12: Nim | C12: Mahasiswa | D12: Nilai
D13: UK3 | E13: UK4 | F13: UK1 (UTS) | G13: UK2 (UAS) | H13: UK5 | L13: NIlai
D14: 0 | E14: 0 | F14: 1 | G14: 1 | H14: 0
A15: 1 | B15: I0322001 | C15: ACHMAD SIDIQ HERMAN | L15: 91
A16: 2 | B16: I0322002 | C16: ADITYA AGUNG NUGROHO | L16: 91
A17: 3 | B17: I0322003 | C17: ADITYA SYAHRIAL VALENTIO
A18: 4 | B18: I0322004 | C18: ADRIANI HASNA KHALISHA | L18: 82
A19: 5 | B19: I0322005 | C19: ADZ-DZIKRA QUROTA A'YUN | L19: 85
A20: 6 | B20: I0322006 | C20: AHMAD JANGKUNG ISLAMUDIN | L20: 82
A21: 7 | B21: I0322007 | C21: AKBAR SATYA PAMBUDI
A22: 8 | B22: I0322008 | C22: AKEYSHA BELVA DEVARA | L22: 89
A23: 9 | B23: I0322009 | C23: AKILA SYAHRA MAHARANI | L23: 92
A24: 10 | B24: I0322010 | C24: ALAMSYAH RIYO SAPUTRA | L24: 89
A25: 11 | B25: I0322011 | C25: ALIF KUS SETYANTO | L25: 89
A26: 12 | B26: I0322012 | C26: ALRANTISA AMIENA RAISA | L26: 85
A27: 13 | B27: I0322013 | C27: ANCELIN ALOYSIA PRASETYO | L27: 91
A28: 14 | B28: I0322014 | C28: ANGELIQUE YOANITA | L28: 82
A29: 15 | B29: I0322015 | C29: ANGGITO DWI PRIHANTORO | L29: 92
A30: 16 | B30: I0322016 | C30: ANTONIUS INDRA WICAKSONO | L30: 89
A31: 17 | B31: I0322017 | C31: ARIIQ RAKHMAN SETIANA | L31: 91
A32: 18 | B32: I0322018 | C32: AUDRY ANGELINA LUBIS | L32: 91
A33: 19 | B33: I0322019 | C33: AURELIA NADIRA ROSEKANIA DARMAWAN | L33: 91
... A43: 29 | B43: I0322029 | C43: CHILYA ULIL FITRIA | L43: 91
A44: 30 | B44: I0322030 | C44: DAFFA RASYAD WIRA NUGROHO
A45: 31 | B45: I0322031 | C45: DANIALIN SISWO HANDOYO | L45: 92
A46: 32 | B46: I0322032 | C46: DANIEL MULASATRIA DAMANIK | L46: 82
A47: 33 | B47: I0322033 | C47: DANU ILMAM AHARY
A48: 34 | B48: I0322034 | C48: DEANIETA ADILEST | L48: 91
A49: 35 | B49: I0322035 | C49: DENNISA LATHIFA HARDIANI | L49: 91

Sheet CP1.30
A2: SEBELAS MARET UNIVERSITY
B4: Faculty | C4: TEKNIK
B5: Study program | C5: Industri
B6: Academic year | C6: 2022 - Ganjil
B7: Course Code | C7: TI191107
B8: Course Name | C8: Menggambar Teknik
B9: Class | C9: A
B10: Lecturer | C10: YUSUF PRIYANDARI
B11: X/lPZv53FpITM7HKFHEpoOUbJenWYS3iLpupsxxW2Jg=
A12: No | B12: Nim | C12: Mahasiswa | D12: Nilai
D13: UK3 | E13: UK4 | F13: UK1 (UTS) | G13: UK2 (UAS) | H13: UK5 | L13: NIlai
D14: 0 | E14: 0 | F14: 1 | G14: 1 | H14: 2
A15: 1 | B15: I0322001 | C15: ACHMAD SIDIQ HERMAN | L15: 87.75
A16: 2 | B16: I0322002 | C16: ADITYA AGUNG NUGROHO | L16: 84
A17: 3 | B17: I0322003 | C17: ADITYA SYAHRIAL VALENTIO
A18: 4 | B18: I0322004 | C18: ADRIANI HASNA KHALISHA | L18: 83
A19: 5 | B19: I0322005 | C19: ADZ-DZIKRA QUROTA A'YUN | L19: 79.75
A20: 6 | B20: I0322006 | C20: AHMAD JANGKUNG ISLAMUDIN | L20: 83
A21: 7 | B21: I0322007 | C21: AKBAR SATYA PAMBUDI
A22: 8 | B22: I0322008 | C22: AKEYSHA BELVA DEVARA | L22: 86.5
A23: 9 | B23: I0322009 | C23: AKILA SYAHRA MAHARANI | L23: 85.75
A24: 10 | B24: I0322010 | C24: ALAMSYAH RIYO SAPUTRA | L24: 86.5
A25: 11 | B25: I0322011 | C25: ALIF KUS SETYANTO | L25: 86.5
A26: 12 | B26: I0322012 | C26: ALRANTISA AMIENA RAISA | L26: 79.75
A27: 13 | B27: I0322013 | C27: ANCELIN ALOYSIA PRASETYO | L27: 84
A28: 14 | B28: I0322014 | C28: ANGELIQUE YOANITA | L28: 83
A29: 15 | B29: I0322015 | C29: ANGGITO DWI PRIHANTORO | L29: 85.75
A30: 16 | B30: I0322016 | C30: ANTONIUS INDRA WICAKSONO | L30: 86.5
A31: 17 | B31: I0322017 | C31: ARIIQ RAKHMAN SETIANA | L31: 87.75
A32: 18 | B32: I0322018 | C32: AUDRY ANGELINA LUBIS | L32: 87.75
A33: 19 | B33: I0322019 | C33: AURELIA NADIRA ROSEKANIA DARMAWAN | L33: 84
... A43: 29 | B43: I0322029 | C43: CHILYA ULIL FITRIA | L43: 87.75
A44: 30 | B44: I0322030 | C44: DAFFA RASYAD WIRA NUGROHO
A45: 31 | B45: I0322031 | C45: DANIALIN SISWO HANDOYO | L45: 85.75
A46: 32 | B46: I0322032 | C46: DANIEL MULASATRIA DAMANIK | L46: 83
A47: 33 | B47: I0322033 | C47: DANU ILMAM AHARY
A48: 34 | B48: I0322034 | C48: DEANIETA ADILEST | I48: I0322034 | J48: 83.333333 | L48: 84
A49: 35 | B49: I0322035 | C49: DENNISA LATHIFA HARDIANI | I49: I0322035 | J49: 82.333333 | L49: 84
